<?xml version="1.0"?>
<robot name="colour_sorting_robot" xmlns:xacro="http://www.ros.org/wiki/xacro">

  <!-- ===== PROPERTIES ===== -->
  <xacro:property name="base_length" value="0.6"/>
  <xacro:property name="base_width"  value="0.4"/>
  <xacro:property name="base_height" value="0.15"/>
  <xacro:property name="wheel_radius" value="0.08"/>
  <xacro:property name="wheel_width"  value="0.05"/>

  <!-- ===== MATERIALS ===== -->
  <material name="grey"> <color rgba="0.5 0.5 0.5 1"/></material>
  <material name="black"><color rgba="0.1 0.1 0.1 1"/></material>
  <material name="blue"> <color rgba="0.0 0.4 0.8 1"/></material>
  <material name="red">  <color rgba="0.8 0.1 0.1 1"/></material>
  <material name="white"><color rgba="1.0 1.0 1.0 1"/></material>

  <!-- ===== BASE FOOTPRINT ===== -->
  <link name="base_footprint"/>

  <joint name="base_footprint_joint" type="fixed">
    <parent link="base_footprint"/>
    <child  link="base_link"/>
    <origin xyz="0 0 ${wheel_radius}" rpy="0 0 0"/>
  </joint>

  <!-- ===== BASE LINK ===== -->
  <link name="base_link">
    <visual>
      <geometry><box size="${base_length} ${base_width} ${base_height}"/></geometry>
      <material name="blue"/>
    </visual>
    <collision>
      <geometry><box size="${base_length} ${base_width} ${base_height}"/></geometry>
    </collision>
    <inertial>
      <origin xyz="0 0 0" rpy="0 0 0"/>
      <mass value="15.0"/>
      <inertia ixx="0.4" ixy="0" ixz="0"
                         iyy="0.4" iyz="0"
                                   izz="0.4"/>
    </inertial>
  </link>

  <!-- ===== WHEEL MACRO ===== -->
  <xacro:macro name="wheel" params="name x y">
    <link name="${name}_wheel_link">
      <visual>
        <geometry><cylinder radius="${wheel_radius}" length="${wheel_width}"/></geometry>
        <material name="black"/>
      </visual>
      <collision>
        <geometry><cylinder radius="${wheel_radius}" length="${wheel_width}"/></geometry>
      </collision>
      <inertial>
        <origin xyz="0 0 0" rpy="0 0 0"/>
        <mass value="1.0"/>
        <inertia ixx="0.002" ixy="0" ixz="0"
                             iyy="0.002" iyz="0"
                                         izz="0.004"/>
      </inertial>
    </link>

    <joint name="${name}_wheel_joint" type="continuous">
      <parent link="base_link"/>
      <child  link="${name}_wheel_link"/>
      <origin xyz="${x} ${y} 0" rpy="-1.5707963 0 0"/>
      <axis xyz="0 0 1"/>
      <dynamics damping="0.1" friction="0.1"/>
    </joint>

    <gazebo reference="${name}_wheel_link">
      <mu1>10.0</mu1>
      <mu2>10.0</mu2>
      <kp>500000.0</kp>
      <kd>10.0</kd>
      <minDepth>0.001</minDepth>
      <maxVel>0.1</maxVel>
      <material>Gazebo/Black</material>
    </gazebo>
  </xacro:macro>

  <xacro:wheel name="left"  x="0.0" y=" 0.225"/>
  <xacro:wheel name="right" x="0.0" y="-0.225"/>

  <!-- ===== CASTER FRONT ===== -->
  <link name="caster_front_link">
    <visual>
      <geometry><sphere radius="0.04"/></geometry>
      <material name="grey"/>
    </visual>
    <collision>
      <geometry><sphere radius="0.04"/></geometry>
    </collision>
    <inertial>
      <mass value="0.5"/>
      <inertia ixx="0.001" ixy="0" ixz="0"
                           iyy="0.001" iyz="0"
                                       izz="0.001"/>
    </inertial>
  </link>
  <joint name="caster_front_joint" type="fixed">
    <parent link="base_link"/>
    <child  link="caster_front_link"/>
    <origin xyz=" 0.25 0.0 -0.04" rpy="0 0 0"/>
  </joint>
  <gazebo reference="caster_front_link">
    <mu1>0.0</mu1>
    <mu2>0.0</mu2>
  </gazebo>

  <!-- ===== CASTER REAR ===== -->
  <link name="caster_rear_link">
    <visual>
      <geometry><sphere radius="0.04"/></geometry>
      <material name="grey"/>
    </visual>
    <collision>
      <geometry><sphere radius="0.04"/></geometry>
    </collision>
    <inertial>
      <mass value="0.5"/>
      <inertia ixx="0.001" ixy="0" ixz="0"
                           iyy="0.001" iyz="0"
                                       izz="0.001"/>
    </inertial>
  </link>
  <joint name="caster_rear_joint" type="fixed">
    <parent link="base_link"/>
    <child  link="caster_rear_link"/>
    <origin xyz="-0.25 0.0 -0.04" rpy="0 0 0"/>
  </joint>
  <gazebo reference="caster_rear_link">
    <mu1>0.0</mu1>
    <mu2>0.0</mu2>
  </gazebo>

  <!-- ===== LIDAR ===== -->
  <link name="lidar_link">
    <visual>
      <geometry><cylinder radius="0.04" length="0.06"/></geometry>
      <material name="black"/>
    </visual>
    <collision>
      <geometry><cylinder radius="0.04" length="0.06"/></geometry>
    </collision>
    <inertial>
      <mass value="0.2"/>
      <inertia ixx="0.001" ixy="0" ixz="0"
                           iyy="0.001" iyz="0"
                                       izz="0.001"/>
    </inertial>
  </link>
  <joint name="lidar_joint" type="fixed">
    <parent link="base_link"/>
    <child  link="lidar_link"/>
    <origin xyz="0.0 0.0 ${base_height/2 + 0.03}" rpy="0 0 0"/>
  </joint>

  <!-- ===== CAMERA ===== -->
  <link name="camera_link">
    <visual>
      <geometry><box size="0.05 0.08 0.05"/></geometry>
      <material name="red"/>
    </visual>
    <collision>
      <geometry><box size="0.05 0.08 0.05"/></geometry>
    </collision>
    <inertial>
      <mass value="0.1"/>
      <inertia ixx="0.001" ixy="0" ixz="0"
                           iyy="0.001" iyz="0"
                                       izz="0.001"/>
    </inertial>
  </link>
  <joint name="camera_joint" type="fixed">
    <parent link="base_link"/>
    <child  link="camera_link"/>
    <origin xyz="${base_length/2 - 0.02} 0.0 ${base_height/2}" rpy="0 0 0"/>
  </joint>

  <link name="camera_optical_link"/>
  <joint name="camera_optical_joint" type="fixed">
    <parent link="camera_link"/>
    <child  link="camera_optical_link"/>
    <origin xyz="0 0 0" rpy="-1.5707 0 -1.5707"/>
  </joint>

  <!-- ===== ARM BASE ===== -->
  <link name="arm_base_link">
    <visual>
      <geometry><box size="0.08 0.08 0.08"/></geometry>
      <material name="grey"/>
    </visual>
    <collision>
      <geometry><box size="0.08 0.08 0.08"/></geometry>
    </collision>
    <inertial>
      <mass value="0.5"/>
      <inertia ixx="0.01" ixy="0" ixz="0"
                          iyy="0.01" iyz="0"
                                     izz="0.01"/>
    </inertial>
  </link>
  <joint name="arm_base_joint" type="fixed">
    <parent link="base_link"/>
    <child  link="arm_base_link"/>
    <origin xyz="${base_length/2 - 0.05} 0.0 ${base_height/2 + 0.04}" rpy="0 0 0"/>
  </joint>

  <!-- ===== ARM LINK 1 ===== -->
  <link name="arm_link1">
    <visual>
      <geometry><box size="0.06 0.06 0.20"/></geometry>
      <material name="grey"/>
    </visual>
    <collision>
      <geometry><box size="0.06 0.06 0.20"/></geometry>
    </collision>
    <inertial>
      <mass value="0.4"/>
      <inertia ixx="0.01" ixy="0" ixz="0"
                          iyy="0.01" iyz="0"
                                     izz="0.01"/>
    </inertial>
  </link>
  <joint name="arm_joint1" type="revolute">
    <parent link="arm_base_link"/>
    <child  link="arm_link1"/>
    <origin xyz="0 0 0.14" rpy="0 0 0"/>
    <axis xyz="0 1 0"/>
    <limit lower="-1.57" upper="1.57" effort="10" velocity="1.0"/>
    <dynamics damping="0.5"/>
  </joint>

  <!-- ===== ARM LINK 2 ===== -->
  <link name="arm_link2">
    <visual>
      <geometry><box size="0.05 0.05 0.18"/></geometry>
      <material name="grey"/>
    </visual>
    <collision>
      <geometry><box size="0.05 0.05 0.18"/></geometry>
    </collision>
    <inertial>
      <mass value="0.3"/>
      <inertia ixx="0.01" ixy="0" ixz="0"
                          iyy="0.01" iyz="0"
                                     izz="0.01"/>
    </inertial>
  </link>
  <joint name="arm_joint2" type="revolute">
    <parent link="arm_link1"/>
    <child  link="arm_link2"/>
    <origin xyz="0 0 0.19" rpy="0 0 0"/>
    <axis xyz="0 1 0"/>
    <limit lower="-1.57" upper="1.57" effort="10" velocity="1.0"/>
    <dynamics damping="0.5"/>
  </joint>

  <!-- ===== GRIPPER LEFT ===== -->
  <link name="gripper_left">
    <visual>
      <geometry><box size="0.02 0.04 0.08"/></geometry>
      <material name="white"/>
    </visual>
    <collision>
      <geometry><box size="0.02 0.04 0.08"/></geometry>
    </collision>
    <inertial>
      <mass value="0.1"/>
      <inertia ixx="0.001" ixy="0" ixz="0"
                           iyy="0.001" iyz="0"
                                       izz="0.001"/>
    </inertial>
  </link>
  <joint name="gripper_left_joint" type="prismatic">
    <parent link="arm_link2"/>
    <child  link="gripper_left"/>
    <origin xyz="0.04 0.0 0.13" rpy="0 0 0"/>
    <axis xyz="0 1 0"/>
    <limit lower="0.0" upper="0.06" effort="5" velocity="0.5"/>
  </joint>

  <!-- ===== GRIPPER RIGHT ===== -->
  <link name="gripper_right">
    <visual>
      <geometry><box size="0.02 0.04 0.08"/></geometry>
      <material name="white"/>
    </visual>
    <collision>
      <geometry><box size="0.02 0.04 0.08"/></geometry>
    </collision>
    <inertial>
      <mass value="0.1"/>
      <inertia ixx="0.001" ixy="0" ixz="0"
                           iyy="0.001" iyz="0"
                                       izz="0.001"/>
    </inertial>
  </link>
  <joint name="gripper_right_joint" type="prismatic">
    <parent link="arm_link2"/>
    <child  link="gripper_right"/>
    <origin xyz="-0.04 0.0 0.13" rpy="0 0 0"/>
    <axis xyz="0 1 0"/>
    <limit lower="-0.06" upper="0.0" effort="5" velocity="0.5"/>
  </joint>

  <!-- ================================================ -->
  <!--         GAZEBO PLUGINS                           -->
  <!-- ================================================ -->

  <!-- Differential Drive Plugin -->
  <gazebo>
    <plugin name="diff_drive" filename="libgazebo_ros_diff_drive.so">
      <updateRate>50</updateRate>
      <leftJoint>left_wheel_joint</leftJoint>
      <rightJoint>right_wheel_joint</rightJoint>
      <wheelSeparation>0.45</wheelSeparation>
      <wheelDiameter>0.16</wheelDiameter>
      <wheelAcceleration>1.0</wheelAcceleration>
      <wheelTorque>20</wheelTorque>
      <commandTopic>cmd_vel</commandTopic>
      <odometryTopic>odom</odometryTopic>
      <odometryFrame>odom</odometryFrame>
      <robotBaseFrame>base_footprint</robotBaseFrame>
      <publishOdomTF>true</publishOdomTF>
      <publishWheelTF>false</publishWheelTF>
      <publishTf>true</publishTf>
      <publishWheelJointState>true</publishWheelJointState>
      <legacyMode>false</legacyMode>
      <rosDebugLevel>na</rosDebugLevel>
    </plugin>
  </gazebo>

  <!-- LiDAR Plugin -->
  <gazebo reference="lidar_link">
    <sensor type="ray" name="lidar_sensor">
      <pose>0 0 0 0 0 0</pose>
      <visualize>true</visualize>
      <update_rate>10</update_rate>
      <ray>
        <scan>
          <horizontal>
            <samples>360</samples>
            <resolution>1</resolution>
            <min_angle>-3.14159</min_angle>
            <max_angle> 3.14159</max_angle>
          </horizontal>
        </scan>
        <range>
          <min>0.15</min>
          <max>10.0</max>
          <resolution>0.01</resolution>
        </range>
      </ray>
      <plugin name="lidar_plugin" filename="libgazebo_ros_laser.so">
        <topicName>/scan</topicName>
        <frameName>lidar_link</frameName>
      </plugin>
    </sensor>
  </gazebo>

  <!-- RGB Camera Plugin -->
  <gazebo reference="camera_link">
    <sensor type="camera" name="rgb_camera">
      <update_rate>30</update_rate>
      <camera name="rgb_camera">
        <horizontal_fov>1.3962634</horizontal_fov>
        <image>
          <width>640</width>
          <height>480</height>
          <format>R8G8B8</format>
        </image>
        <clip><near>0.02</near><far>300</far></clip>
      </camera>
      <plugin name="camera_plugin" filename="libgazebo_ros_camera.so">
        <alwaysOn>true</alwaysOn>
        <updateRate>30</updateRate>
        <cameraName>rgb_camera</cameraName>
        <imageTopicName>/camera/image_raw</imageTopicName>
        <cameraInfoTopicName>/camera/camera_info</cameraInfoTopicName>
        <frameName>camera_optical_link</frameName>
      </plugin>
    </sensor>
  </gazebo>

  <gazebo reference="base_link">
    <material>Gazebo/Blue</material>
  </gazebo>

</robot>
